Workbook

Sheet DB
D3: Current scheme slab | O3: Current scheme slab
A4: State | B4: Zone | C4: Total # Dealers | D4: A | E4: B | F4: C | G4: D | H4: E | K4: Distributor Name | L4: State | M4: Zone | N4: Total # Dealers | O4: A | P4: B | Q4: C | R4: D | S4: E
A5: CHHATTISGARH | B5: =IFERROR(VLOOKUP(A5,$L$5:$M$69,2,0),"-") -> Central | C5: =SUMIFS(N$5:N$69,$L$5:$L$69,$A5,$M$5:$M$69,$B5) -> 38 | D5: =SUMIFS(O$5:O$69,$L$5:$L$69,$A5,$M$5:$M$69,$B5) -> 0 | E5: =SUMIFS(P$5:P$69,$L$5:$L$69,$A5,$M$5:$M$69,$B5) -> 0 | F5: =SUMIFS(Q$5:Q$69,$L$5:$L$69,$A5,$M$5:$M$69,$B5) -> 0 | G5: =SUMIFS(R$5:R$69,$L$5:$L$69,$A5,$M$5:$M$69,$B5) -> 0 | H5: =SUMIFS(S$5:S$69,$L$5:$L$69,$A5,$M$5:$M$69,$B5) -> 0 | K5: AGGARWAL TRADERS | L5: JAMMU AND KASHMIR | M5: North | N5: =COUNTIFS('FY 26_qualification scenario'!$I:$I,DB!$K5,'FY 26_qualification scenario'!$F:$F,DB!$L5,'FY 26_qualification scenario'!$M:$M,DB!$M5) -> 34 | O5: =COUNTIFS('FY 26_qualification scenario'!$BI:$BI,DB!O$4,'FY 26_qualification scenario'!$I:$I,DB!$K5,'FY 26_qualification scenario'!$F:$F,DB!$L5,'FY 26_qualification scenario'!$M:$M,DB!$M5) -> 1 | P5: =COUNTIFS('FY 26_qualification scenario'!$BI:$BI,DB!P$4,'FY 26_qualification scenario'!$I:$I,DB!$K5,'FY 26_qualification scenario'!$F:$F,DB!$L5,'FY 26_qualification scenario'!$M:$M,DB!$M5) -> 1 | Q5: =COUNTIFS('FY 26_qualification scenario'!$BI:$BI,DB!Q$4,'FY 26_qualification scenario'!$I:$I,DB!$K5,'FY 26_qualification scenario'!$F:$F,DB!$L5,'FY 26_qualification scenario'!$M:$M,DB!$M5) -> 1 | R5: =COUNTIFS('FY 26_qualification scenario'!$BI:$BI,DB!R$4,'FY 26_qualification scenario'!$I:$I,DB!$K5,'FY 26_qualification scenario'!$F:$F,DB!$L5,'FY 26_qualification scenario'!$M:$M,DB!$M5) -> 0 | S5: =COUNTIFS('FY 26_qualification scenario'!$BI:$BI,DB!S$4,'FY 26_qualification scenario'!$I:$I,DB!$K5,'FY 26_qualification scenario'!$F:$F,DB!$L5,'FY 26_qualification scenario'!$M:$M,DB!$M5) -> 0
A6: MADHYA PRADESH | B6: =IFERROR(VLOOKUP(A6,$L$5:$M$69,2,0),"-") -> Central | C6: =SUMIFS(N$5:N$69,$L$5:$L$69,$A6,$M$5:$M$69,$B6) -> 142 | D6: =SUMIFS(O$5:O$69,$L$5:$L$69,$A6,$M$5:$M$69,$B6) -> 5 | E6: =SUMIFS(P$5:P$69,$L$5:$L$69,$A6,$M$5:$M$69,$B6) -> 2 | F6: =SUMIFS(Q$5:Q$69,$L$5:$L$69,$A6,$M$5:$M$69,$B6) -> 3 | G6: =SUMIFS(R$5:R$69,$L$5:$L$69,$A6,$M$5:$M$69,$B6) -> 4 | H6: =SUMIFS(S$5:S$69,$L$5:$L$69,$A6,$M$5:$M$69,$B6) -> 1 | K6: Amco Associates | L6: JHARKHAND | M6: East | N6: =COUNTIFS('FY 26_qualification scenario'!$I:$I,DB!$K6,'FY 26_qualification scenario'!$F:$F,DB!$L6,'FY 26_qualification scenario'!$M:$M,DB!$M6) -> 5 | O6: =COUNTIFS('FY 26_qualification scenario'!$BI:$BI,DB!O$4,'FY 26_qualification scenario'!$I:$I,DB!$K6,'FY 26_qualification scenario'!$F:$F,DB!$L6,'FY 26_qualification scenario'!$M:$M,DB!$M6) -> 0 | P6: =COUNTIFS('FY 26_qualification scenario'!$BI:$BI,DB!P$4,'FY 26_qualification scenario'!$I:$I,DB!$K6,'FY 26_qualification scenario'!$F:$F,DB!$L6,'FY 26_qualification scenario'!$M:$M,DB!$M6) -> 0 | Q6: =COUNTIFS('FY 26_qualification scenario'!$BI:$BI,DB!Q$4,'FY 26_qualification scenario'!$I:$I,DB!$K6,'FY 26_qualification scenario'!$F:$F,DB!$L6,'FY 26_qualification scenario'!$M:$M,DB!$M6) -> 0 | R6: =COUNTIFS('FY 26_qualification scenario'!$BI:$BI,DB!R$4,'FY 26_qualification scenario'!$I:$I,DB!$K6,'FY 26_qualification scenario'!$F:$F,DB!$L6,'FY 26_qualification scenario'!$M:$M,DB!$M6) -> 0 | S6: =COUNTIFS('FY 26_qualification scenario'!$BI:$BI,DB!S$4,'FY 26_qualification scenario'!$I:$I,DB!$K6,'FY 26_qualification scenario'!$F:$F,DB!$L6,'FY 26_qualification scenario'!$M:$M,DB!$M6) -> 0
A7: ODISHA | B7: =IFERROR(VLOOKUP(A7,$L$5:$M$69,2,0),"-") -> Central | C7: =SUMIFS(N$5:N$69,$L$5:$L$69,$A7,$M$5:$M$69,$B7) -> 136 | D7: =SUMIFS(O$5:O$69,$L$5:$L$69,$A7,$M$5:$M$69,$B7) -> 1 | E7: =SUMIFS(P$5:P$69,$L$5:$L$69,$A7,$M$5:$M$69,$B7) -> 5 | F7: =SUMIFS(Q$5:Q$69,$L$5:$L$69,$A7,$M$5:$M$69,$B7) -> 1 | G7: =SUMIFS(R$5:R$69,$L$5:$L$69,$A7,$M$5:$M$69,$B7) -> 0 | H7: =SUMIFS(S$5:S$69,$L$5:$L$69,$A7,$M$5:$M$69,$B7) -> 0 | K7: ARS INFRA | L7: GUJARAT | M7: West | N7: =COUNTIFS('FY 26_qualification scenario'!$I:$I,DB!$K7,'FY 26_qualification scenario'!$F:$F,DB!$L7,'FY 26_qualification scenario'!$M:$M,DB!$M7) -> 2 | O7: =COUNTIFS('FY 26_qualification scenario'!$BI:$BI,DB!O$4,'FY 26_qualification scenario'!$I:$I,DB!$K7,'FY 26_qualification scenario'!$F:$F,DB!$L7,'FY 26_qualification scenario'!$M:$M,DB!$M7) -> 0 | P7: =COUNTIFS('FY 26_qualification scenario'!$BI:$BI,DB!P$4,'FY 26_qualification scenario'!$I:$I,DB!$K7,'FY 26_qualification scenario'!$F:$F,DB!$L7,'FY 26_qualification scenario'!$M:$M,DB!$M7) -> 0 | Q7: =COUNTIFS('FY 26_qualification scenario'!$BI:$BI,DB!Q$4,'FY 26_qualification scenario'!$I:$I,DB!$K7,'FY 26_qualification scenario'!$F:$F,DB!$L7,'FY 26_qualification scenario'!$M:$M,DB!$M7) -> 0 | R7: =COUNTIFS('FY 26_qualification scenario'!$BI:$BI,DB!R$4,'FY 26_qualification scenario'!$I:$I,DB!$K7,'FY 26_qualification scenario'!$F:$F,DB!$L7,'FY 26_qualification scenario'!$M:$M,DB!$M7) -> 0 | S7: =COUNTIFS('FY 26_qualification scenario'!$BI:$BI,DB!S$4,'FY 26_qualification scenario'!$I:$I,DB!$K7,'FY 26_qualification scenario'!$F:$F,DB!$L7,'FY 26_qualification scenario'!$M:$M,DB!$M7) -> 0
A8: MAHARASHTRA | B8: =IFERROR(VLOOKUP(A8,$L$5:$M$69,2,0),"-") -> Central | C8: =SUMIFS(N$5:N$69,$L$5:$L$69,$A8,$M$5:$M$69,$B8) -> 1 | D8: =SUMIFS(O$5:O$69,$L$5:$L$69,$A8,$M$5:$M$69,$B8) -> 0 | E8: =SUMIFS(P$5:P$69,$L$5:$L$69,$A8,$M$5:$M$69,$B8) -> 0 | F8: =SUMIFS(Q$5:Q$69,$L$5:$L$69,$A8,$M$5:$M$69,$B8) -> 0 | G8: =SUMIFS(R$5:R$69,$L$5:$L$69,$A8,$M$5:$M$69,$B8) -> 0 | H8: =SUMIFS(S$5:S$69,$L$5:$L$69,$A8,$M$5:$M$69,$B8) -> 0 | K8: BD ISPAT AND ALLOYS | L8: RAJASTHAN | M8: North | N8: =COUNTIFS('FY 26_qualification scenario'!$I:$I,DB!$K8,'FY 26_qualification scenario'!$F:$F,DB!$L8,'FY 26_qualification scenario'!$M:$M,DB!$M8) -> 1 | O8: =COUNTIFS('FY 26_qualification scenario'!$BI:$BI,DB!O$4,'FY 26_qualification scenario'!$I:$I,DB!$K8,'FY 26_qualification scenario'!$F:$F,DB!$L8,'FY 26_qualification scenario'!$M:$M,DB!$M8) -> 0 | P8: =COUNTIFS('FY 26_qualification scenario'!$BI:$BI,DB!P$4,'FY 26_qualification scenario'!$I:$I,DB!$K8,'FY 26_qualification scenario'!$F:$F,DB!$L8,'FY 26_qualification scenario'!$M:$M,DB!$M8) -> 0 | Q8: =COUNTIFS('FY 26_qualification scenario'!$BI:$BI,DB!Q$4,'FY 26_qualification scenario'!$I:$I,DB!$K8,'FY 26_qualification scenario'!$F:$F,DB!$L8,'FY 26_qualification scenario'!$M:$M,DB!$M8) -> 0 | R8: =COUNTIFS('FY 26_qualification scenario'!$BI:$BI,DB!R$4,'FY 26_qualification scenario'!$I:$I,DB!$K8,'FY 26_qualification scenario'!$F:$F,DB!$L8,'FY 26_qualification scenario'!$M:$M,DB!$M8) -> 0 | S8: =COUNTIFS('FY 26_qualification scenario'!$BI:$BI,DB!S$4,'FY 26_qualification scenario'!$I:$I,DB!$K8,'FY 26_qualification scenario'!$F:$F,DB!$L8,'FY 26_qualification scenario'!$M:$M,DB!$M8) -> 0
A9: JHARKHAND | B9: =IFERROR(VLOOKUP(A9,$L$5:$M$69,2,0),"-") -> East | C9: =SUMIFS(N$5:N$69,$L$5:$L$69,$A9,$M$5:$M$69,$B9) -> 35 | D9: =SUMIFS(O$5:O$69,$L$5:$L$69,$A9,$M$5:$M$69,$B9) -> 1 | E9: =SUMIFS(P$5:P$69,$L$5:$L$69,$A9,$M$5:$M$69,$B9) -> 0 | F9: =SUMIFS(Q$5:Q$69,$L$5:$L$69,$A9,$M$5:$M$69,$B9) -> 0 | G9: =SUMIFS(R$5:R$69,$L$5:$L$69,$A9,$M$5:$M$69,$B9) -> 0 | H9: =SUMIFS(S$5:S$69,$L$5:$L$69,$A9,$M$5:$M$69,$B9) -> 0 | K9: CHANDRA TRADERS | L9: WEST BENGAL | M9: East | N9: =COUNTIFS('FY 26_qualification scenario'!$I:$I,DB!$K9,'FY 26_qualification scenario'!$F:$F,DB!$L9,'FY 26_qualification scenario'!$M:$M,DB!$M9) -> 26 | O9: =COUNTIFS('FY 26_qualification scenario'!$BI:$BI,DB!O$4,'FY 26_qualification scenario'!$I:$I,DB!$K9,'FY 26_qualification scenario'!$F:$F,DB!$L9,'FY 26_qualification scenario'!$M:$M,DB!$M9) -> 0 | P9: =COUNTIFS('FY 26_qualification scenario'!$BI:$BI,DB!P$4,'FY 26_qualification scenario'!$I:$I,DB!$K9,'FY 26_qualification scenario'!$F:$F,DB!$L9,'FY 26_qualification scenario'!$M:$M,DB!$M9) -> 0 | Q9: =COUNTIFS('FY 26_qualification scenario'!$BI:$BI,DB!Q$4,'FY 26_qualification scenario'!$I:$I,DB!$K9,'FY 26_qualification scenario'!$F:$F,DB!$L9,'FY 26_qualification scenario'!$M:$M,DB!$M9) -> 0 | R9: =COUNTIFS('FY 26_qualification scenario'!$BI:$BI,DB!R$4,'FY 26_qualification scenario'!$I:$I,DB!$K9,'FY 26_qualification scenario'!$F:$F,DB!$L9,'FY 26_qualification scenario'!$M:$M,DB!$M9) -> 0 | S9: =COUNTIFS('FY 26_qualification scenario'!$BI:$BI,DB!S$4,'FY 26_qualification scenario'!$I:$I,DB!$K9,'FY 26_qualification scenario'!$F:$F,DB!$L9,'FY 26_qualification scenario'!$M:$M,DB!$M9) -> 0
A10: WEST BENGAL | B10: =IFERROR(VLOOKUP(A10,$L$5:$M$69,2,0),"-") -> East | C10: =SUMIFS(N$5:N$69,$L$5:$L$69,$A10,$M$5:$M$69,$B10) -> 119 | D10: =SUMIFS(O$5:O$69,$L$5:$L$69,$A10,$M$5:$M$69,$B10) -> 0 | E10: =SUMIFS(P$5:P$69,$L$5:$L$69,$A10,$M$5:$M$69,$B10) -> 0 | F10: =SUMIFS(Q$5:Q$69,$L$5:$L$69,$A10,$M$5:$M$69,$B10) -> 0 | G10: =SUMIFS(R$5:R$69,$L$5:$L$69,$A10,$M$5:$M$69,$B10) -> 0 | H10: =SUMIFS(S$5:S$69,$L$5:$L$69,$A10,$M$5:$M$69,$B10) -> 0 | K10: DINESH STEEL PRIVATE LIMITED | L10: UTTAR PRADESH | M10: North | N10: =COUNTIFS('FY 26_qualification scenario'!$I:$I,DB!$K10,'FY 26_qualification scenario'!$F:$F,DB!$L10,'FY 26_qualification scenario'!$M:$M,DB!$M10) -> 45 | O10: =COUNTIFS('FY 26_qualification scenario'!$BI:$BI,DB!O$4,'FY 26_qualification scenario'!$I:$I,DB!$K10,'FY 26_qualification scenario'!$F:$F,DB!$L10,'FY 26_qualification scenario'!$M:$M,DB!$M10) -> 3 | P10: =COUNTIFS('FY 26_qualification scenario'!$BI:$BI,DB!P$4,'FY 26_qualification scenario'!$I:$I,DB!$K10,'FY 26_qualification scenario'!$F:$F,DB!$L10,'FY 26_qualification scenario'!$M:$M,DB!$M10) -> 3 | Q10: =COUNTIFS('FY 26_qualification scenario'!$BI:$BI,DB!Q$4,'FY 26_qualification scenario'!$I:$I,DB!$K10,'FY 26_qualification scenario'!$F:$F,DB!$L10,'FY 26_qualification scenario'!$M:$M,DB!$M10) -> 1 | R10: =COUNTIFS('FY 26_qualification scenario'!$BI:$BI,DB!R$4,'FY 26_qualification scenario'!$I:$I,DB!$K10,'FY 26_qualification scenario'!$F:$F,DB!$L10,'FY 26_qualification scenario'!$M:$M,DB!$M10) -> 0 | S10: =COUNTIFS('FY 26_qualification scenario'!$BI:$BI,DB!S$4,'FY 26_qualification scenario'!$I:$I,DB!$K10,'FY 26_qualification scenario'!$F:$F,DB!$L10,'FY 26_qualification scenario'!$M:$M,DB!$M10) -> 0
A11: BIHAR | B11: =IFERROR(VLOOKUP(A11,$L$5:$M$69,2,0),"-") -> East | C11: =SUMIFS(N$5:N$69,$L$5:$L$69,$A11,$M$5:$M$69,$B11) -> 49 | D11: =SUMIFS(O$5:O$69,$L$5:$L$69,$A11,$M$5:$M$69,$B11) -> 1 | E11: =SUMIFS(P$5:P$69,$L$5:$L$69,$A11,$M$5:$M$69,$B11) -> 0 | F11: =SUMIFS(Q$5:Q$69,$L$5:$L$69,$A11,$M$5:$M$69,$B11) -> 0 | G11: =SUMIFS(R$5:R$69,$L$5:$L$69,$A11,$M$5:$M$69,$B11) -> 0 | H11: =SUMIFS(S$5:S$69,$L$5:$L$69,$A11,$M$5:$M$69,$B11) -> 0 | K11: FAIRDEAL STEELS | L11: JAMMU AND KASHMIR | M11: North | N11: =COUNTIFS('FY 26_qualification scenario'!$I:$I,DB!$K11,'FY 26_qualification scenario'!$F:$F,DB!$L11,'FY 26_qualification scenario'!$M:$M,DB!$M11) -> 1 | O11: =COUNTIFS('FY 26_qualification scenario'!$BI:$BI,DB!O$4,'FY 26_qualification scenario'!$I:$I,DB!$K11,'FY 26_qualification scenario'!$F:$F,DB!$L11,'FY 26_qualification scenario'!$M:$M,DB!$M11) -> 0 | P11: =COUNTIFS('FY 26_qualification scenario'!$BI:$BI,DB!P$4,'FY 26_qualification scenario'!$I:$I,DB!$K11,'FY 26_qualification scenario'!$F:$F,DB!$L11,'FY 26_qualification scenario'!$M:$M,DB!$M11) -> 0 | Q11: =COUNTIFS('FY 26_qualification scenario'!$BI:$BI,DB!Q$4,'FY 26_qualification scenario'!$I:$I,DB!$K11,'FY 26_qualification scenario'!$F:$F,DB!$L11,'FY 26_qualification scenario'!$M:$M,DB!$M11) -> 0 | R11: =COUNTIFS('FY 26_qualification scenario'!$BI:$BI,DB!R$4,'FY 26_qualification scenario'!$I:$I,DB!$K11,'FY 26_qualification scenario'!$F:$F,DB!$L11,'FY 26_qualification scenario'!$M:$M,DB!$M11) -> 0 | S11: =COUNTIFS('FY 26_qualification scenario'!$BI:$BI,DB!S$4,'FY 26_qualification scenario'!$I:$I,DB!$K11,'FY 26_qualification scenario'!$F:$F,DB!$L11,'FY 26_qualification scenario'!$M:$M,DB!$M11) -> 0
A12: SIKKIM | B12: =IFERROR(VLOOKUP(A12,$L$5:$M$69,2,0),"-") -> East | C12: =SUMIFS(N$5:N$69,$L$5:$L$69,$A12,$M$5:$M$69,$B12) -> 1 | D12: =SUMIFS(O$5:O$69,$L$5:$L$69,$A12,$M$5:$M$69,$B12) -> 0 | E12: =SUMIFS(P$5:P$69,$L$5:$L$69,$A12,$M$5:$M$69,$B12) -> 0 | F12: =SUMIFS(Q$5:Q$69,$L$5:$L$69,$A12,$M$5:$M$69,$B12) -> 0 | G12: =SUMIFS(R$5:R$69,$L$5:$L$69,$A12,$M$5:$M$69,$B12) -> 0 | H12: =SUMIFS(S$5:S$69,$L$5:$L$69,$A12,$M$5:$M$69,$B12) -> 0 | K12: G.C. Steels (India) Pvt. Ltd. | L12: HARYANA | M12: North | N12: =COUNTIFS('FY 26_qualification scenario'!$I:$I,DB!$K12,'FY 26_qualification scenario'!$F:$F,DB!$L12,'FY 26_qualification scenario'!$M:$M,DB!$M12) -> 7 | O12: =COUNTIFS('FY 26_qualification scenario'!$BI:$BI,DB!O$4,'FY 26_qualification scenario'!$I:$I,DB!$K12,'FY 26_qualification scenario'!$F:$F,DB!$L12,'FY 26_qualification scenario'!$M:$M,DB!$M12) -> 0 | P12: =COUNTIFS('FY 26_qualification scenario'!$BI:$BI,DB!P$4,'FY 26_qualification scenario'!$I:$I,DB!$K12,'FY 26_qualification scenario'!$F:$F,DB!$L12,'FY 26_qualification scenario'!$M:$M,DB!$M12) -> 0 | Q12: =COUNTIFS('FY 26_qualification scenario'!$BI:$BI,DB!Q$4,'FY 26_qualification scenario'!$I:$I,DB!$K12,'FY 26_qualification scenario'!$F:$F,DB!$L12,'FY 26_qualification scenario'!$M:$M,DB!$M12) -> 0 | R12: =COUNTIFS('FY 26_qualification scenario'!$BI:$BI,DB!R$4,'FY 26_qualification scenario'!$I:$I,DB!$K12,'FY 26_qualification scenario'!$F:$F,DB!$L12,'FY 26_qualification scenario'!$M:$M,DB!$M12) -> 0 | S12: =COUNTIFS('FY 26_qualification scenario'!$BI:$BI,DB!S$4,'FY 26_qualification scenario'!$I:$I,DB!$K12,'FY 26_qualification scenario'!$F:$F,DB!$L12,'FY 26_qualification scenario'!$M:$M,DB!$M12) -> 0
A13: MADHYA PRADESH | B13: North | C13: =SUMIFS(N$5:N$69,$L$5:$L$69,$A13,$M$5:$M$69,$B13) -> 23 | D13: =SUMIFS(O$5:O$69,$L$5:$L$69,$A13,$M$5:$M$69,$B13) -> 1 | E13: =SUMIFS(P$5:P$69,$L$5:$L$69,$A13,$M$5:$M$69,$B13) -> 0 | F13: =SUMIFS(Q$5:Q$69,$L$5:$L$69,$A13,$M$5:$M$69,$B13) -> 0 | G13: =SUMIFS(R$5:R$69,$L$5:$L$69,$A13,$M$5:$M$69,$B13) -> 0 | H13: =SUMIFS(S$5:S$69,$L$5:$L$69,$A13,$M$5:$M$69,$B13) -> 0 | K13: GLOBAL IRONTRADING PVT. LTD. | L13: UTTAR PRADESH | M13: North | N13: =COUNTIFS('FY 26_qualification scenario'!$I:$I,DB!$K13,'FY 26_qualification scenario'!$F:$F,DB!$L13,'FY 26_qualification scenario'!$M:$M,DB!$M13) -> 26 | O13: =COUNTIFS('FY 26_qualification scenario'!$BI:$BI,DB!O$4,'FY 26_qualification scenario'!$I:$I,DB!$K13,'FY 26_qualification scenario'!$F:$F,DB!$L13,'FY 26_qualification scenario'!$M:$M,DB!$M13) -> 1 | P13: =COUNTIFS('FY 26_qualification scenario'!$BI:$BI,DB!P$4,'FY 26_qualification scenario'!$I:$I,DB!$K13,'FY 26_qualification scenario'!$F:$F,DB!$L13,'FY 26_qualification scenario'!$M:$M,DB!$M13) -> 1 | Q13: =COUNTIFS('FY 26_qualification scenario'!$BI:$BI,DB!Q$4,'FY 26_qualification scenario'!$I:$I,DB!$K13,'FY 26_qualification scenario'!$F:$F,DB!$L13,'FY 26_qualification scenario'!$M:$M,DB!$M13) -> 1 | R13: =COUNTIFS('FY 26_qualification scenario'!$BI:$BI,DB!R$4,'FY 26_qualification scenario'!$I:$I,DB!$K13,'FY 26_qualification scenario'!$F:$F,DB!$L13,'FY 26_qualification scenario'!$M:$M,DB!$M13) -> 0 | S13: =COUNTIFS('FY 26_qualification scenario'!$BI:$BI,DB!S$4,'FY 26_qualification scenario'!$I:$I,DB!$K13,'FY 26_qualification scenario'!$F:$F,DB!$L13,'FY 26_qualification scenario'!$M:$M,DB!$M13) -> 0
A14: JAMMU AND KASHMIR | B14: =IFERROR(VLOOKUP(A14,$L$5:$M$69,2,0),"-") -> North | C14: =SUMIFS(N$5:N$69,$L$5:$L$69,$A14,$M$5:$M$69,$B14) -> 43 | D14: =SUMIFS(O$5:O$69,$L$5:$L$69,$A14,$M$5:$M$69,$B14) -> 1 | E14: =SUMIFS(P$5:P$69,$L$5:$L$69,$A14,$M$5:$M$69,$B14) -> 1 | F14: =SUMIFS(Q$5:Q$69,$L$5:$L$69,$A14,$M$5:$M$69,$B14) -> 1 | G14: =SUMIFS(R$5:R$69,$L$5:$L$69,$A14,$M$5:$M$69,$B14) -> 0 | H14: =SUMIFS(S$5:S$69,$L$5:$L$69,$A14,$M$5:$M$69,$B14) -> 0 | K14: Global Steel | L14: CHHATTISGARH | M14: Central | N14: =COUNTIFS('FY 26_qualification scenario'!$I:$I,DB!$K14,'FY 26_qualification scenario'!$F:$F,DB!$L14,'FY 26_qualification scenario'!$M:$M,DB!$M14) -> 4 | O14: =COUNTIFS('FY 26_qualification scenario'!$BI:$BI,DB!O$4,'FY 26_qualification scenario'!$I:$I,DB!$K14,'FY 26_qualification scenario'!$F:$F,DB!$L14,'FY 26_qualification scenario'!$M:$M,DB!$M14) -> 0 | P14: =COUNTIFS('FY 26_qualification scenario'!$BI:$BI,DB!P$4,'FY 26_qualification scenario'!$I:$I,DB!$K14,'FY 26_qualification scenario'!$F:$F,DB!$L14,'FY 26_qualification scenario'!$M:$M,DB!$M14) -> 0 | Q14: =COUNTIFS('FY 26_qualification scenario'!$BI:$BI,DB!Q$4,'FY 26_qualification scenario'!$I:$I,DB!$K14,'FY 26_qualification scenario'!$F:$F,DB!$L14,'FY 26_qualification scenario'!$M:$M,DB!$M14) -> 0 | R14: =COUNTIFS('FY 26_qualification scenario'!$BI:$BI,DB!R$4,'FY 26_qualification scenario'!$I:$I,DB!$K14,'FY 26_qualification scenario'!$F:$F,DB!$L14,'FY 26_qualification scenario'!$M:$M,DB!$M14) -> 0 | S14: =COUNTIFS('FY 26_qualification scenario'!$BI:$BI,DB!S$4,'FY 26_qualification scenario'!$I:$I,DB!$K14,'FY 26_qualification scenario'!$F:$F,DB!$L14,'FY 26_qualification scenario'!$M:$M,DB!$M14) -> 0
A15: RAJASTHAN | B15: =IFERROR(VLOOKUP(A15,$L$5:$M$69,2,0),"-") -> North | C15: =SUMIFS(N$5:N$69,$L$5:$L$69,$A15,$M$5:$M$69,$B15) -> 210 | D15: =SUMIFS(O$5:O$69,$L$5:$L$69,$A15,$M$5:$M$69,$B15) -> 8 | E15: =SUMIFS(P$5:P$69,$L$5:$L$69,$A15,$M$5:$M$69,$B15) -> 12 | F15: =SUMIFS(Q$5:Q$69,$L$5:$L$69,$A15,$M$5:$M$69,$B15) -> 3 | G15: =SUMIFS(R$5:R$69,$L$5:$L$69,$A15,$M$5:$M$69,$B15) -> 7 | H15: =SUMIFS(S$5:S$69,$L$5:$L$69,$A15,$M$5:$M$69,$B15) -> 0 | K15: Global Steel | L15: MADHYA PRADESH | M15: Central | N15: =COUNTIFS('FY 26_qualification scenario'!$I:$I,DB!$K15,'FY 26_qualification scenario'!$F:$F,DB!$L15,'FY 26_qualification scenario'!$M:$M,DB!$M15) -> 71 | O15: =COUNTIFS('FY 26_qualification scenario'!$BI:$BI,DB!O$4,'FY 26_qualification scenario'!$I:$I,DB!$K15,'FY 26_qualification scenario'!$F:$F,DB!$L15,'FY 26_qualification scenario'!$M:$M,DB!$M15) -> 4 | P15: =COUNTIFS('FY 26_qualification scenario'!$BI:$BI,DB!P$4,'FY 26_qualification scenario'!$I:$I,DB!$K15,'FY 26_qualification scenario'!$F:$F,DB!$L15,'FY 26_qualification scenario'!$M:$M,DB!$M15) -> 0 | Q15: =COUNTIFS('FY 26_qualification scenario'!$BI:$BI,DB!Q$4,'FY 26_qualification scenario'!$I:$I,DB!$K15,'FY 26_qualification scenario'!$F:$F,DB!$L15,'FY 26_qualification scenario'!$M:$M,DB!$M15) -> 2 | R15: =COUNTIFS('FY 26_qualification scenario'!$BI:$BI,DB!R$4,'FY 26_qualification scenario'!$I:$I,DB!$K15,'FY 26_qualification scenario'!$F:$F,DB!$L15,'FY 26_qualification scenario'!$M:$M,DB!$M15) -> 1 | S15: =COUNTIFS('FY 26_qualification scenario'!$BI:$BI,DB!S$4,'FY 26_qualification scenario'!$I:$I,DB!$K15,'FY 26_qualification scenario'!$F:$F,DB!$L15,'FY 26_qualification scenario'!$M:$M,DB!$M15) -> 0
A16: UTTAR PRADESH | B16: =IFERROR(VLOOKUP(A16,$L$5:$M$69,2,0),"-") -> North | C16: =SUMIFS(N$5:N$69,$L$5:$L$69,$A16,$M$5:$M$69,$B16) -> 378 | D16: =SUMIFS(O$5:O$69,$L$5:$L$69,$A16,$M$5:$M$69,$B16) -> 13 | E16: =SUMIFS(P$5:P$69,$L$5:$L$69,$A16,$M$5:$M$69,$B16) -> 11 | F16: =SUMIFS(Q$5:Q$69,$L$5:$L$69,$A16,$M$5:$M$69,$B16) -> 2 | G16: =SUMIFS(R$5:R$69,$L$5:$L$69,$A16,$M$5:$M$69,$B16) -> 8 | H16: =SUMIFS(S$5:S$69,$L$5:$L$69,$A16,$M$5:$M$69,$B16) -> 1 | K16: GOBINDGARH IRON LLP | L16: UTTAR PRADESH | M16: North | N16: =COUNTIFS('FY 26_qualification scenario'!$I:$I,DB!$K16,'FY 26_qualification scenario'!$F:$F,DB!$L16,'FY 26_qualification scenario'!$M:$M,DB!$M16) -> 67 | O16: =COUNTIFS('FY 26_qualification scenario'!$BI:$BI,DB!O$4,'FY 26_qualification scenario'!$I:$I,DB!$K16,'FY 26_qualification scenario'!$F:$F,DB!$L16,'FY 26_qualification scenario'!$M:$M,DB!$M16) -> 1 | P16: =COUNTIFS('FY 26_qualification scenario'!$BI:$BI,DB!P$4,'FY 26_qualification scenario'!$I:$I,DB!$K16,'FY 26_qualification scenario'!$F:$F,DB!$L16,'FY 26_qualification scenario'!$M:$M,DB!$M16) -> 0 | Q16: =COUNTIFS('FY 26_qualification scenario'!$BI:$BI,DB!Q$4,'FY 26_qualification scenario'!$I:$I,DB!$K16,'FY 26_qualification scenario'!$F:$F,DB!$L16,'FY 26_qualification scenario'!$M:$M,DB!$M16) -> 0 | R16: =COUNTIFS('FY 26_qualification scenario'!$BI:$BI,DB!R$4,'FY 26_qualification scenario'!$I:$I,DB!$K16,'FY 26_qualification scenario'!$F:$F,DB!$L16,'FY 26_qualification scenario'!$M:$M,DB!$M16) -> 0 | S16: =COUNTIFS('FY 26_qualification scenario'!$BI:$BI,DB!S$4,'FY 26_qualification scenario'!$I:$I,DB!$K16,'FY 26_qualification scenario'!$F:$F,DB!$L16,'FY 26_qualification scenario'!$M:$M,DB!$M16) -> 0
A17: HARYANA | B17: =IFERROR(VLOOKUP(A17,$L$5:$M$69,2,0),"-") -> North | C17: =SUMIFS(N$5:N$69,$L$5:$L$69,$A17,$M$5:$M$69,$B17) -> 280 | D17: =SUMIFS(O$5:O$69,$L$5:$L$69,$A17,$M$5:$M$69,$B17) -> 8 | E17: =SUMIFS(P$5:P$69,$L$5:$L$69,$A17,$M$5:$M$69,$B17) -> 22 | F17: =SUMIFS(Q$5:Q$69,$L$5:$L$69,$A17,$M$5:$M$69,$B17) -> 13 | G17: =SUMIFS(R$5:R$69,$L$5:$L$69,$A17,$M$5:$M$69,$B17) -> 19 | H17: =SUMIFS(S$5:S$69,$L$5:$L$69,$A17,$M$5:$M$69,$B17) -> 5 | K17: GOLDWIN ISPAT PRIVATE LIMITED | L17: ODISHA | M17: Central | N17: =COUNTIFS('FY 26_qualification scenario'!$I:$I,DB!$K17,'FY 26_qualification scenario'!$F:$F,DB!$L17,'FY 26_qualification scenario'!$M:$M,DB!$M17) -> 6 | O17: =COUNTIFS('FY 26_qualification scenario'!$BI:$BI,DB!O$4,'FY 26_qualification scenario'!$I:$I,DB!$K17,'FY 26_qualification scenario'!$F:$F,DB!$L17,'FY 26_qualification scenario'!$M:$M,DB!$M17) -> 0 | P17: =COUNTIFS('FY 26_qualification scenario'!$BI:$BI,DB!P$4,'FY 26_qualification scenario'!$I:$I,DB!$K17,'FY 26_qualification scenario'!$F:$F,DB!$L17,'FY 26_qualification scenario'!$M:$M,DB!$M17) -> 1 | Q17: =COUNTIFS('FY 26_qualification scenario'!$BI:$BI,DB!Q$4,'FY 26_qualification scenario'!$I:$I,DB!$K17,'FY 26_qualification scenario'!$F:$F,DB!$L17,'FY 26_qualification scenario'!$M:$M,DB!$M17) -> 0 | R17: =COUNTIFS('FY 26_qualification scenario'!$BI:$BI,DB!R$4,'FY 26_qualification scenario'!$I:$I,DB!$K17,'FY 26_qualification scenario'!$F:$F,DB!$L17,'FY 26_qualification scenario'!$M:$M,DB!$M17) -> 0 | S17: =COUNTIFS('FY 26_qualification scenario'!$BI:$BI,DB!S$4,'FY 26_qualification scenario'!$I:$I,DB!$K17,'FY 26_qualification scenario'!$F:$F,DB!$L17,'FY 26_qualification scenario'!$M:$M,DB!$M17) -> 0
A18: PUNJAB | B18: =IFERROR(VLOOKUP(A18,$L$5:$M$69,2,0),"-") -> North | C18: =SUMIFS(N$5:N$69,$L$5:$L$69,$A18,$M$5:$M$69,$B18) -> 111 | D18: =SUMIFS(O$5:O$69,$L$5:$L$69,$A18,$M$5:$M$69,$B18) -> 5 | E18: =SUMIFS(P$5:P$69,$L$5:$L$69,$A18,$M$5:$M$69,$B18) -> 3 | F18: =SUMIFS(Q$5:Q$69,$L$5:$L$69,$A18,$M$5:$M$69,$B18) -> 0 | G18: =SUMIFS(R$5:R$69,$L$5:$L$69,$A18,$M$5:$M$69,$B18) -> 1 | H18: =SUMIFS(S$5:S$69,$L$5:$L$69,$A18,$M$5:$M$69,$B18) -> 1 | K18: J P ALLOYS | L18: RAJASTHAN | M18: North | N18: =COUNTIFS('FY 26_qualification scenario'!$I:$I,DB!$K18,'FY 26_qualification scenario'!$F:$F,DB!$L18,'FY 26_qualification scenario'!$M:$M,DB!$M18) -> 72 | O18: =COUNTIFS('FY 26_qualification scenario'!$BI:$BI,DB!O$4,'FY 26_qualification scenario'!$I:$I,DB!$K18,'FY 26_qualification scenario'!$F:$F,DB!$L18,'FY 26_qualification scenario'!$M:$M,DB!$M18) -> 1 | P18: =COUNTIFS('FY 26_qualification scenario'!$BI:$BI,DB!P$4,'FY 26_qualification scenario'!$I:$I,DB!$K18,'FY 26_qualification scenario'!$F:$F,DB!$L18,'FY 26_qualification scenario'!$M:$M,DB!$M18) -> 6 | Q18: =COUNTIFS('FY 26_qualification scenario'!$BI:$BI,DB!Q$4,'FY 26_qualification scenario'!$I:$I,DB!$K18,'FY 26_qualification scenario'!$F:$F,DB!$L18,'FY 26_qualification scenario'!$M:$M,DB!$M18) -> 1 | R18: =COUNTIFS('FY 26_qualification scenario'!$BI:$BI,DB!R$4,'FY 26_qualification scenario'!$I:$I,DB!$K18,'FY 26_qualification scenario'!$F:$F,DB!$L18,'FY 26_qualification scenario'!$M:$M,DB!$M18) -> 5 | S18: =COUNTIFS('FY 26_qualification scenario'!$BI:$BI,DB!S$4,'FY 26_qualification scenario'!$I:$I,DB!$K18,'FY 26_qualification scenario'!$F:$F,DB!$L18,'FY 26_qualification scenario'!$M:$M,DB!$M18) -> 0
A19: DELHI | B19: =IFERROR(VLOOKUP(A19,$L$5:$M$69,2,0),"-") -> North | C19: =SUMIFS(N$5:N$69,$L$5:$L$69,$A19,$M$5:$M$69,$B19) -> 79 | D19: =SUMIFS(O$5:O$69,$L$5:$L$69,$A19,$M$5:$M$69,$B19) -> 3 | E19: =SUMIFS(P$5:P$69,$L$5:$L$69,$A19,$M$5:$M$69,$B19) -> 2 | F19: =SUMIFS(Q$5:Q$69,$L$5:$L$69,$A19,$M$5:$M$69,$B19) -> 2 | G19: =SUMIFS(R$5:R$69,$L$5:$L$69,$A19,$M$5:$M$69,$B19) -> 1 | H19: =SUMIFS(S$5:S$69,$L$5:$L$69,$A19,$M$5:$M$69,$B19) -> 1 | K19: JAI DURGA STEELS | L19: HARYANA | M19: North | N19: =COUNTIFS('FY 26_qualification scenario'!$I:$I,DB!$K19,'FY 26_qualification scenario'!$F:$F,DB!$L19,'FY 26_qualification scenario'!$M:$M,DB!$M19) -> 45 | O19: =COUNTIFS('FY 26_qualification scenario'!$BI:$BI,DB!O$4,'FY 26_qualification scenario'!$I:$I,DB!$K19,'FY 26_qualification scenario'!$F:$F,DB!$L19,'FY 26_qualification scenario'!$M:$M,DB!$M19) -> 1 | P19: =COUNTIFS('FY 26_qualification scenario'!$BI:$BI,DB!P$4,'FY 26_qualification scenario'!$I:$I,DB!$K19,'FY 26_qualification scenario'!$F:$F,DB!$L19,'FY 26_qualification scenario'!$M:$M,DB!$M19) -> 4 | Q19: =COUNTIFS('FY 26_qualification scenario'!$BI:$BI,DB!Q$4,'FY 26_qualification scenario'!$I:$I,DB!$K19,'FY 26_qualification scenario'!$F:$F,DB!$L19,'FY 26_qualification scenario'!$M:$M,DB!$M19) -> 4 | R19: =COUNTIFS('FY 26_qualification scenario'!$BI:$BI,DB!R$4,'FY 26_qualification scenario'!$I:$I,DB!$K19,'FY 26_qualification scenario'!$F:$F,DB!$L19,'FY 26_qualification scenario'!$M:$M,DB!$M19) -> 9 | S19: =COUNTIFS('FY 26_qualification scenario'!$BI:$BI,DB!S$4,'FY 26_qualification scenario'!$I:$I,DB!$K19,'FY 26_qualification scenario'!$F:$F,DB!$L19,'FY 26_qualification scenario'!$M:$M,DB!$M19) -> 2
A20: HIMACHAL PRADESH | B20: =IFERROR(VLOOKUP(A20,$L$5:$M$69,2,0),"-") -> North | C20: =SUMIFS(N$5:N$69,$L$5:$L$69,$A20,$M$5:$M$69,$B20) -> 19 | D20: =SUMIFS(O$5:O$69,$L$5:$L$69,$A20,$M$5:$M$69,$B20) -> 0 | E20: =SUMIFS(P$5:P$69,$L$5:$L$69,$A20,$M$5:$M$69,$B20) -> 0 | F20: =SUMIFS(Q$5:Q$69,$L$5:$L$69,$A20,$M$5:$M$69,$B20) -> 0 | G20: =SUMIFS(R$5:R$69,$L$5:$L$69,$A20,$M$5:$M$69,$B20) -> 1 | H20: =SUMIFS(S$5:S$69,$L$5:$L$69,$A20,$M$5:$M$69,$B20) -> 0 | K20: JAI MATA DI STEELS | L20: WEST BENGAL | M20: East | N20: =COUNTIFS('FY 26_qualification scenario'!$I:$I,DB!$K20,'FY 26_qualification scenario'!$F:$F,DB!$L20,'FY 26_qualification scenario'!$M:$M,DB!$M20) -> 8 | O20: =COUNTIFS('FY 26_qualification scenario'!$BI:$BI,DB!O$4,'FY 26_qualification scenario'!$I:$I,DB!$K20,'FY 26_qualification scenario'!$F:$F,DB!$L20,'FY 26_qualification scenario'!$M:$M,DB!$M20) -> 0 | P20: =COUNTIFS('FY 26_qualification scenario'!$BI:$BI,DB!P$4,'FY 26_qualification scenario'!$I:$I,DB!$K20,'FY 26_qualification scenario'!$F:$F,DB!$L20,'FY 26_qualification scenario'!$M:$M,DB!$M20) -> 0 | Q20: =COUNTIFS('FY 26_qualification scenario'!$BI:$BI,DB!Q$4,'FY 26_qualification scenario'!$I:$I,DB!$K20,'FY 26_qualification scenario'!$F:$F,DB!$L20,'FY 26_qualification scenario'!$M:$M,DB!$M20) -> 0 | R20: =COUNTIFS('FY 26_qualification scenario'!$BI:$BI,DB!R$4,'FY 26_qualification scenario'!$I:$I,DB!$K20,'FY 26_qualification scenario'!$F:$F,DB!$L20,'FY 26_qualification scenario'!$M:$M,DB!$M20) -> 0 | S20: =COUNTIFS('FY 26_qualification scenario'!$BI:$BI,DB!S$4,'FY 26_qualification scenario'!$I:$I,DB!$K20,'FY 26_qualification scenario'!$F:$F,DB!$L20,'FY 26_qualification scenario'!$M:$M,DB!$M20) -> 0
A21: CHANDIGARH | B21: =IFERROR(VLOOKUP(A21,$L$5:$M$69,2,0),"-") -> North | C21: =SUMIFS(N$5:N$69,$L$5:$L$69,$A21,$M$5:$M$69,$B21) -> 5 | D21: =SUMIFS(O$5:O$69,$L$5:$L$69,$A21,$M$5:$M$69,$B21) -> 0 | E21: =SUMIFS(P$5:P$69,$L$5:$L$69,$A21,$M$5:$M$69,$B21) -> 0 | F21: =SUMIFS(Q$5:Q$69,$L$5:$L$69,$A21,$M$5:$M$69,$B21) -> 0 | G21: =SUMIFS(R$5:R$69,$L$5:$L$69,$A21,$M$5:$M$69,$B21) -> 0 | H21: =SUMIFS(S$5:S$69,$L$5:$L$69,$A21,$M$5:$M$69,$B21) -> 0 | K21: K P ENTERPRISES | L21: UTTAR PRADESH | M21: North | N21: =COUNTIFS('FY 26_qualification scenario'!$I:$I,DB!$K21,'FY 26_qualification scenario'!$F:$F,DB!$L21,'FY 26_qualification scenario'!$M:$M,DB!$M21) -> 4 | O21: =COUNTIFS('FY 26_qualification scenario'!$BI:$BI,DB!O$4,'FY 26_qualification scenario'!$I:$I,DB!$K21,'FY 26_qualification scenario'!$F:$F,DB!$L21,'FY 26_qualification scenario'!$M:$M,DB!$M21) -> 0 | P21: =COUNTIFS('FY 26_qualification scenario'!$BI:$BI,DB!P$4,'FY 26_qualification scenario'!$I:$I,DB!$K21,'FY 26_qualification scenario'!$F:$F,DB!$L21,'FY 26_qualification scenario'!$M:$M,DB!$M21) -> 0 | Q21: =COUNTIFS('FY 26_qualification scenario'!$BI:$BI,DB!Q$4,'FY 26_qualification scenario'!$I:$I,DB!$K21,'FY 26_qualification scenario'!$F:$F,DB!$L21,'FY 26_qualification scenario'!$M:$M,DB!$M21) -> 0 | R21: =COUNTIFS('FY 26_qualification scenario'!$BI:$BI,DB!R$4,'FY 26_qualification scenario'!$I:$I,DB!$K21,'FY 26_qualification scenario'!$F:$F,DB!$L21,'FY 26_qualification scenario'!$M:$M,DB!$M21) -> 0 | S21: =COUNTIFS('FY 26_qualification scenario'!$BI:$BI,DB!S$4,'FY 26_qualification scenario'!$I:$I,DB!$K21,'FY 26_qualification scenario'!$F:$F,DB!$L21,'FY 26_qualification scenario'!$M:$M,DB!$M21) -> 0
A22: UTTARAKHAND | B22: =IFERROR(VLOOKUP(A22,$L$5:$M$69,2,0),"-") -> North | C22: =SUMIFS(N$5:N$69,$L$5:$L$69,$A22,$M$5:$M$69,$B22) -> 74 | D22: =SUMIFS(O$5:O$69,$L$5:$L$69,$A22,$M$5:$M$69,$B22) -> 3 | E22: =SUMIFS(P$5:P$69,$L$5:$L$69,$A22,$M$5:$M$69,$B22) -> 1 | F22: =SUMIFS(Q$5:Q$69,$L$5:$L$69,$A22,$M$5:$M$69,$B22) -> 0 | G22: =SUMIFS(R$5:R$69,$L$5:$L$69,$A22,$M$5:$M$69,$B22) -> 0 | H22: =SUMIFS(S$5:S$69,$L$5:$L$69,$A22,$M$5:$M$69,$B22) -> 0 | K22: KASHMIR IRON TRADER | L22: JAMMU AND KASHMIR | M22: North | N22: =COUNTIFS('FY 26_qualification scenario'!$I:$I,DB!$K22,'FY 26_qualification scenario'!$F:$F,DB!$L22,'FY 26_qualification scenario'!$M:$M,DB!$M22) -> 2 | O22: =COUNTIFS('FY 26_qualification scenario'!$BI:$BI,DB!O$4,'FY 26_qualification scenario'!$I:$I,DB!$K22,'FY 26_qualification scenario'!$F:$F,DB!$L22,'FY 26_qualification scenario'!$M:$M,DB!$M22) -> 0 | P22: =COUNTIFS('FY 26_qualification scenario'!$BI:$BI,DB!P$4,'FY 26_qualification scenario'!$I:$I,DB!$K22,'FY 26_qualification scenario'!$F:$F,DB!$L22,'FY 26_qualification scenario'!$M:$M,DB!$M22) -> 0 | Q22: =COUNTIFS('FY 26_qualification scenario'!$BI:$BI,DB!Q$4,'FY 26_qualification scenario'!$I:$I,DB!$K22,'FY 26_qualification scenario'!$F:$F,DB!$L22,'FY 26_qualification scenario'!$M:$M,DB!$M22) -> 0 | R22: =COUNTIFS('FY 26_qualification scenario'!$BI:$BI,DB!R$4,'FY 26_qualification scenario'!$I:$I,DB!$K22,'FY 26_qualification scenario'!$F:$F,DB!$L22,'FY 26_qualification scenario'!$M:$M,DB!$M22) -> 0 | S22: =COUNTIFS('FY 26_qualification scenario'!$BI:$BI,DB!S$4,'FY 26_qualification scenario'!$I:$I,DB!$K22,'FY 26_qualification scenario'!$F:$F,DB!$L22,'FY 26_qualification scenario'!$M:$M,DB!$M22) -> 0
A23: GUJARAT | B23: =IFERROR(VLOOKUP(A23,$L$5:$M$69,2,0),"-") -> West | C23: =SUMIFS(N$5:N$69,$L$5:$L$69,$A23,$M$5:$M$69,$B23) -> 2 | D23: =SUMIFS(O$5:O$69,$L$5:$L$69,$A23,$M$5:$M$69,$B23) -> 0 | E23: =SUMIFS(P$5:P$69,$L$5:$L$69,$A23,$M$5:$M$69,$B23) -> 0 | F23: =SUMIFS(Q$5:Q$69,$L$5:$L$69,$A23,$M$5:$M$69,$B23) -> 0 | G23: =SUMIFS(R$5:R$69,$L$5:$L$69,$A23,$M$5:$M$69,$B23) -> 0 | H23: =SUMIFS(S$5:S$69,$L$5:$L$69,$A23,$M$5:$M$69,$B23) -> 0 | K23: KEDIA PIPES PRIVATE LMITED | L23: WEST BENGAL | M23: East | N23: =COUNTIFS('FY 26_qualification scenario'!$I:$I,DB!$K23,'FY 26_qualification scenario'!$F:$F,DB!$L23,'FY 26_qualification scenario'!$M:$M,DB!$M23) -> 12 | O23: =COUNTIFS('FY 26_qualification scenario'!$BI:$BI,DB!O$4,'FY 26_qualification scenario'!$I:$I,DB!$K23,'FY 26_qualification scenario'!$F:$F,DB!$L23,'FY 26_qualification scenario'!$M:$M,DB!$M23) -> 0 | P23: =COUNTIFS('FY 26_qualification scenario'!$BI:$BI,DB!P$4,'FY 26_qualification scenario'!$I:$I,DB!$K23,'FY 26_qualification scenario'!$F:$F,DB!$L23,'FY 26_qualification scenario'!$M:$M,DB!$M23) -> 0 | Q23: =COUNTIFS('FY 26_qualification scenario'!$BI:$BI,DB!Q$4,'FY 26_qualification scenario'!$I:$I,DB!$K23,'FY 26_qualification scenario'!$F:$F,DB!$L23,'FY 26_qualification scenario'!$M:$M,DB!$M23) -> 0 | R23: =COUNTIFS('FY 26_qualification scenario'!$BI:$BI,DB!R$4,'FY 26_qualification scenario'!$I:$I,DB!$K23,'FY 26_qualification scenario'!$F:$F,DB!$L23,'FY 26_qualification scenario'!$M:$M,DB!$M23) -> 0 | S23: =COUNTIFS('FY 26_qualification scenario'!$BI:$BI,DB!S$4,'FY 26_qualification scenario'!$I:$I,DB!$K23,'FY 26_qualification scenario'!$F:$F,DB!$L23,'FY 26_qualification scenario'!$M:$M,DB!$M23) -> 0
A24: Total | C24: =SUM(C5:C23) -> 1745 | D24: =SUM(D5:D23) -> 50 | E24: =SUM(E5:E23) -> 59 | F24: =SUM(F5:F23) -> 25 | G24: =SUM(G5:G23) -> 41 | H24: =SUM(H5:H23) -> 9 | K24: Khandelwal Associates | L24: UTTAR PRADESH | M24: North | N24: =COUNTIFS('FY 26_qualification scenario'!$I:$I,DB!$K24,'FY 26_qualification scenario'!$F:$F,DB!$L24,'FY 26_qualification scenario'!$M:$M,DB!$M24) -> 23 | O24: =COUNTIFS('FY 26_qualification scenario'!$BI:$BI,DB!O$4,'FY 26_qualification scenario'!$I:$I,DB!$K24,'FY 26_qualification scenario'!$F:$F,DB!$L24,'FY 26_qualification scenario'!$M:$M,DB!$M24) -> 3 | P24: =COUNTIFS('FY 26_qualification scenario'!$BI:$BI,DB!P$4,'FY 26_qualification scenario'!$I:$I,DB!$K24,'FY 26_qualification scenario'!$F:$F,DB!$L24,'FY 26_qualification scenario'!$M:$M,DB!$M24) -> 1 | Q24: =COUNTIFS('FY 26_qualification scenario'!$BI:$BI,DB!Q$4,'FY 26_qualification scenario'!$I:$I,DB!$K24,'FY 26_qualification scenario'!$F:$F,DB!$L24,'FY 26_qualification scenario'!$M:$M,DB!$M24) -> 0 | R24: =COUNTIFS('FY 26_qualification scenario'!$BI:$BI,DB!R$4,'FY 26_qualification scenario'!$I:$I,DB!$K24,'FY 26_qualification scenario'!$F:$F,DB!$L24,'FY 26_qualification scenario'!$M:$M,DB!$M24) -> 0 | S24: =COUNTIFS('FY 26_qualification scenario'!$BI:$BI,DB!S$4,'FY 26_qualification scenario'!$I:$I,DB!$K24,'FY 26_qualification scenario'!$F:$F,DB!$L24,'FY 26_qualification scenario'!$M:$M,DB!$M24) -> 1
K25: KHARAKIA METALS PRIVATE LIMITED | L25: BIHAR | M25: East | N25: =COUNTIFS('FY 26_qualification scenario'!$I:$I,DB!$K25,'FY 26_qualification scenario'!$F:$F,DB!$L25,'FY 26_qualification scenario'!$M:$M,DB!$M25) -> 23 | O25: =COUNTIFS('FY 26_qualification scenario'!$BI:$BI,DB!O$4,'FY 26_qualification scenario'!$I:$I,DB!$K25,'FY 26_qualification scenario'!$F:$F,DB!$L25,'FY 26_qualification scenario'!$M:$M,DB!$M25) -> 1 | P25: =COUNTIFS('FY 26_qualification scenario'!$BI:$BI,DB!P$4,'FY 26_qualification scenario'!$I:$I,DB!$K25,'FY 26_qualification scenario'!$F:$F,DB!$L25,'FY 26_qualification scenario'!$M:$M,DB!$M25) -> 0 | Q25: =COUNTIFS('FY 26_qualification scenario'!$BI:$BI,DB!Q$4,'FY 26_qualification scenario'!$I:$I,DB!$K25,'FY 26_qualification scenario'!$F:$F,DB!$L25,'FY 26_qualification scenario'!$M:$M,DB!$M25) -> 0 | R25: =COUNTIFS('FY 26_qualification scenario'!$BI:$BI,DB!R$4,'FY 26_qualification scenario'!$I:$I,DB!$K25,'FY 26_qualification scenario'!$F:$F,DB!$L25,'FY 26_qualification scenario'!$M:$M,DB!$M25) -> 0 | S25: =COUNTIFS('FY 26_qualification scenario'!$BI:$BI,DB!S$4,'FY 26_qualification scenario'!$I:$I,DB!$K25,'FY 26_qualification scenario'!$F:$F,DB!$L25,'FY 26_qualification scenario'!$M:$M,DB!$M25) -> 0
K26: KHUNTETA STEELS | L26: RAJASTHAN | M26: North | N26: =COUNTIFS('FY 26_qualification scenario'!$I:$I,DB!$K26,'FY 26_qualification scenario'!$F:$F,DB!$L26,'FY 26_qualification scenario'!$M:$M,DB!$M26) -> 23 | O26: =COUNTIFS('FY 26_qualification scenario'!$BI:$BI,DB!O$4,'FY 26_qualification scenario'!$I:$I,DB!$K26,'FY 26_qualification scenario'!$F:$F,DB!$L26,'FY 26_qualification scenario'!$M:$M,DB!$M26) -> 0 | P26: =COUNTIFS('FY 26_qualification scenario'!$BI:$BI,DB!P$4,'FY 26_qualification scenario'!$I:$I,DB!$K26,'FY 26_qualification scenario'!$F:$F,DB!$L26,'FY 26_qualification scenario'!$M:$M,DB!$M26) -> 0 | Q26: =COUNTIFS('FY 26_qualification scenario'!$BI:$BI,DB!Q$4,'FY 26_qualification scenario'!$I:$I,DB!$K26,'FY 26_qualification scenario'!$F:$F,DB!$L26,'FY 26_qualification scenario'!$M:$M,DB!$M26) -> 0 | R26: =COUNTIFS('FY 26_qualification scenario'!$BI:$BI,DB!R$4,'FY 26_qualification scenario'!$I:$I,DB!$K26,'FY 26_qualification scenario'!$F:$F,DB!$L26,'FY 26_qualification scenario'!$M:$M,DB!$M26) -> 0 | S26: =COUNTIFS('FY 26_qualification scenario'!$BI:$BI,DB!S$4,'FY 26_qualification scenario'!$I:$I,DB!$K26,'FY 26_qualification scenario'!$F:$F,DB!$L26,'FY 26_qualification scenario'!$M:$M,DB!$M26) -> 0
K27: LAXMI ENTERPRISES | L27: CHHATTISGARH | M27: Central | N27: =COUNTIFS('FY 26_qualification scenario'!$I:$I,DB!$K27,'FY 26_qualification scenario'!$F:$F,DB!$L27,'FY 26_qualification scenario'!$M:$M,DB!$M27) -> 4 | O27: =COUNTIFS('FY 26_qualification scenario'!$BI:$BI,DB!O$4,'FY 26_qualification scenario'!$I:$I,DB!$K27,'FY 26_qualification scenario'!$F:$F,DB!$L27,'FY 26_qualification scenario'!$M:$M,DB!$M27) -> 0 | P27: =COUNTIFS('FY 26_qualification scenario'!$BI:$BI,DB!P$4,'FY 26_qualification scenario'!$I:$I,DB!$K27,'FY 26_qualification scenario'!$F:$F,DB!$L27,'FY 26_qualification scenario'!$M:$M,DB!$M27) -> 0 | Q27: =COUNTIFS('FY 26_qualification scenario'!$BI:$BI,DB!Q$4,'FY 26_qualification scenario'!$I:$I,DB!$K27,'FY 26_qualification scenario'!$F:$F,DB!$L27,'FY 26_qualification scenario'!$M:$M,DB!$M27) -> 0 | R27: =COUNTIFS('FY 26_qualification scenario'!$BI:$BI,DB!R$4,'FY 26_qualification scenario'!$I:$I,DB!$K27,'FY 26_qualification scenario'!$F:$F,DB!$L27,'FY 26_qualification scenario'!$M:$M,DB!$M27) -> 0 | S27: =COUNTIFS('FY 26_qualification scenario'!$BI:$BI,DB!S$4,'FY 26_qualification scenario'!$I:$I,DB!$K27,'FY 26_qualification scenario'!$F:$F,DB!$L27,'FY 26_qualification scenario'!$M:$M,DB!$M27) -> 0
K28: M R Associates | L28: RAJASTHAN | M28: North | N28: =COUNTIFS('FY 26_qualification scenario'!$I:$I,DB!$K28,'FY 26_qualification scenario'!$F:$F,DB!$L28,'FY 26_qualification scenario'!$M:$M,DB!$M28) -> 42 | O28: =COUNTIFS('FY 26_qualification scenario'!$BI:$BI,DB!O$4,'FY 26_qualification scenario'!$I:$I,DB!$K28,'FY 26_qualification scenario'!$F:$F,DB!$L28,'FY 26_qualification scenario'!$M:$M,DB!$M28) -> 4 | P28: =COUNTIFS('FY 26_qualification scenario'!$BI:$BI,DB!P$4,'FY 26_qualification scenario'!$I:$I,DB!$K28,'FY 26_qualification scenario'!$F:$F,DB!$L28,'FY 26_qualification scenario'!$M:$M,DB!$M28) -> 4 | Q28: =COUNTIFS('FY 26_qualification scenario'!$BI:$BI,DB!Q$4,'FY 26_qualification scenario'!$I:$I,DB!$K28,'FY 26_qualification scenario'!$F:$F,DB!$L28,'FY 26_qualification scenario'!$M:$M,DB!$M28) -> 1 | R28: =COUNTIFS('FY 26_qualification scenario'!$BI:$BI,DB!R$4,'FY 26_qualification scenario'!$I:$I,DB!$K28,'FY 26_qualification scenario'!$F:$F,DB!$L28,'FY 26_qualification scenario'!$M:$M,DB!$M28) -> 1 | S28: =COUNTIFS('FY 26_qualification scenario'!$BI:$BI,DB!S$4,'FY 26_qualification scenario'!$I:$I,DB!$K28,'FY 26_qualification scenario'!$F:$F,DB!$L28,'FY 26_qualification scenario'!$M:$M,DB!$M28) -> 0
K29: M/S JAI BALAJEE ENTERPRISES | L29: JHARKHAND | M29: East | N29: =COUNTIFS('FY 26_qualification scenario'!$I:$I,DB!$K29,'FY 26_qualification scenario'!$F:$F,DB!$L29,'FY 26_qualification scenario'!$M:$M,DB!$M29) -> 5 | O29: =COUNTIFS('FY 26_qualification scenario'!$BI:$BI,DB!O$4,'FY 26_qualification scenario'!$I:$I,DB!$K29,'FY 26_qualification scenario'!$F:$F,DB!$L29,'FY 26_qualification scenario'!$M:$M,DB!$M29) -> 0 | P29: =COUNTIFS('FY 26_qualification scenario'!$BI:$BI,DB!P$4,'FY 26_qualification scenario'!$I:$I,DB!$K29,'FY 26_qualification scenario'!$F:$F,DB!$L29,'FY 26_qualification scenario'!$M:$M,DB!$M29) -> 0 | Q29: =COUNTIFS('FY 26_qualification scenario'!$BI:$BI,DB!Q$4,'FY 26_qualification scenario'!$I:$I,DB!$K29,'FY 26_qualification scenario'!$F:$F,DB!$L29,'FY 26_qualification scenario'!$M:$M,DB!$M29) -> 0 | R29: =COUNTIFS('FY 26_qualification scenario'!$BI:$BI,DB!R$4,'FY 26_qualification scenario'!$I:$I,DB!$K29,'FY 26_qualification scenario'!$F:$F,DB!$L29,'FY 26_qualification scenario'!$M:$M,DB!$M29) -> 0 | S29: =COUNTIFS('FY 26_qualification scenario'!$BI:$BI,DB!S$4,'FY 26_qualification scenario'!$I:$I,DB!$K29,'FY 26_qualification scenario'!$F:$F,DB!$L29,'FY 26_qualification scenario'!$M:$M,DB!$M29) -> 0
K30: M/s REAL DREAMS ENTERPRISES | L30: JHARKHAND | M30: East | N30: =COUNTIFS('FY 26_qualification scenario'!$I:$I,DB!$K30,'FY 26_qualification scenario'!$F:$F,DB!$L30,'FY 26_qualification scenario'!$M:$M,DB!$M30) -> 25 | O30: =COUNTIFS('FY 26_qualification scenario'!$BI:$BI,DB!O$4,'FY 26_qualification scenario'!$I:$I,DB!$K30,'FY 26_qualification scenario'!$F:$F,DB!$L30,'FY 26_qualification scenario'!$M:$M,DB!$M30) -> 1 | P30: =COUNTIFS('FY 26_qualification scenario'!$BI:$BI,DB!P$4,'FY 26_qualification scenario'!$I:$I,DB!$K30,'FY 26_qualification scenario'!$F:$F,DB!$L30,'FY 26_qualification scenario'!$M:$M,DB!$M30) -> 0 | Q30: =COUNTIFS('FY 26_qualification scenario'!$BI:$BI,DB!Q$4,'FY 26_qualification scenario'!$I:$I,DB!$K30,'FY 26_qualification scenario'!$F:$F,DB!$L30,'FY 26_qualification scenario'!$M:$M,DB!$M30) -> 0 | R30: =COUNTIFS('FY 26_qualification scenario'!$BI:$BI,DB!R$4,'FY 26_qualification scenario'!$I:$I,DB!$K30,'FY 26_qualification scenario'!$F:$F,DB!$L30,'FY 26_qualification scenario'!$M:$M,DB!$M30) -> 0 | S30: =COUNTIFS('FY 26_qualification scenario'!$BI:$BI,DB!S$4,'FY 26_qualification scenario'!$I:$I,DB!$K30,'FY 26_qualification scenario'!$F:$F,DB!$L30,'FY 26_qualification scenario'!$M:$M,DB!$M30) -> 0
K31: M/S TIRUPATI SALES | L31: JHARKHAND | M31: East | N31: =COUNTIFS('FY 26_qualification scenario'!$I:$I,DB!$K31,'FY 26_qualification scenario'!$F:$F,DB!$L31,'FY 26_qualification scenario'!$M:$M,DB!$M31) -> 0 | O31: =COUNTIFS('FY 26_qualification scenario'!$BI:$BI,DB!O$4,'FY 26_qualification scenario'!$I:$I,DB!$K31,'FY 26_qualification scenario'!$F:$F,DB!$L31,'FY 26_qualification scenario'!$M:$M,DB!$M31) -> 0 | P31: =COUNTIFS('FY 26_qualification scenario'!$BI:$BI,DB!P$4,'FY 26_qualification scenario'!$I:$I,DB!$K31,'FY 26_qualification scenario'!$F:$F,DB!$L31,'FY 26_qualification scenario'!$M:$M,DB!$M31) -> 0 | Q31: =COUNTIFS('FY 26_qualification scenario'!$BI:$BI,DB!Q$4,'FY 26_qualification scenario'!$I:$I,DB!$K31,'FY 26_qualification scenario'!$F:$F,DB!$L31,'FY 26_qualification scenario'!$M:$M,DB!$M31) -> 0 | R31: =COUNTIFS('FY 26_qualification scenario'!$BI:$BI,DB!R$4,'FY 26_qualification scenario'!$I:$I,DB!$K31,'FY 26_qualification scenario'!$F:$F,DB!$L31,'FY 26_qualification scenario'!$M:$M,DB!$M31) -> 0 | S31: =COUNTIFS('FY 26_qualification scenario'!$BI:$BI,DB!S$4,'FY 26_qualification scenario'!$I:$I,DB!$K31,'FY 26_qualification scenario'!$F:$F,DB!$L31,'FY 26_qualification scenario'!$M:$M,DB!$M31) -> 0
K32: MADHYA BHARAT ISPAT PRIVATE LIMITED | L32: CHHATTISGARH | M32: Central | N32: =COUNTIFS('FY 26_qualification scenario'!$I:$I,DB!$K32,'FY 26_qualification scenario'!$F:$F,DB!$L32,'FY 26_qualification scenario'!$M:$M,DB!$M32) -> 18 | O32: =COUNTIFS('FY 26_qualification scenario'!$BI:$BI,DB!O$4,'FY 26_qualification scenario'!$I:$I,DB!$K32,'FY 26_qualification scenario'!$F:$F,DB!$L32,'FY 26_qualification scenario'!$M:$M,DB!$M32) -> 0 | P32: =COUNTIFS('FY 26_qualification scenario'!$BI:$BI,DB!P$4,'FY 26_qualification scenario'!$I:$I,DB!$K32,'FY 26_qualification scenario'!$F:$F,DB!$L32,'FY 26_qualification scenario'!$M:$M,DB!$M32) -> 0 | Q32: =COUNTIFS('FY 26_qualification scenario'!$BI:$BI,DB!Q$4,'FY 26_qualification scenario'!$I:$I,DB!$K32,'FY 26_qualification scenario'!$F:$F,DB!$L32,'FY 26_qualification scenario'!$M:$M,DB!$M32) -> 0 | R32: =COUNTIFS('FY 26_qualification scenario'!$BI:$BI,DB!R$4,'FY 26_qualification scenario'!$I:$I,DB!$K32,'FY 26_qualification scenario'!$F:$F,DB!$L32,'FY 26_qualification scenario'!$M:$M,DB!$M32) -> 0 | S32: =COUNTIFS('FY 26_qualification scenario'!$BI:$BI,DB!S$4,'FY 26_qualification scenario'!$I:$I,DB!$K32,'FY 26_qualification scenario'!$F:$F,DB!$L32,'FY 26_qualification scenario'!$M:$M,DB!$M32) -> 0
K33: MAHAVIR STEEL CORPORATION | L33: PUNJAB | M33: North | N33: =COUNTIFS('FY 26_qualification scenario'!$I:$I,DB!$K33,'FY 26_qualification scenario'!$F:$F,DB!$L33,'FY 26_qualification scenario'!$M:$M,DB!$M33) -> 31 | O33: =COUNTIFS('FY 26_qualification scenario'!$BI:$BI,DB!O$4,'FY 26_qualification scenario'!$I:$I,DB!$K33,'FY 26_qualification scenario'!$F:$F,DB!$L33,'FY 26_qualification scenario'!$M:$M,DB!$M33) -> 1 | P33: =COUNTIFS('FY 26_qualification scenario'!$BI:$BI,DB!P$4,'FY 26_qualification scenario'!$I:$I,DB!$K33,'FY 26_qualification scenario'!$F:$F,DB!$L33,'FY 26_qualification scenario'!$M:$M,DB!$M33) -> 1 | Q33: =COUNTIFS('FY 26_qualification scenario'!$BI:$BI,DB!Q$4,'FY 26_qualification scenario'!$I:$I,DB!$K33,'FY 26_qualification scenario'!$F:$F,DB!$L33,'FY 26_qualification scenario'!$M:$M,DB!$M33) -> 0 | R33: =COUNTIFS('FY 26_qualification scenario'!$BI:$BI,DB!R$4,'FY 26_qualification scenario'!$I:$I,DB!$K33,'FY 26_qualification scenario'!$F:$F,DB!$L33,'FY 26_qualification scenario'!$M:$M,DB!$M33) -> 0 | S33: =COUNTIFS('FY 26_qualification scenario'!$BI:$BI,DB!S$4,'FY 26_qualification scenario'!$I:$I,DB!$K33,'FY 26_qualification scenario'!$F:$F,DB!$L33,'FY 26_qualification scenario'!$M:$M,DB!$M33) -> 0
K34: MAHENDRA STEELS | L34: DELHI | M34: North | N34: =COUNTIFS('FY 26_qualification scenario'!$I:$I,DB!$K34,'FY 26_qualification scenario'!$F:$F,DB!$L34,'FY 26_qualification scenario'!$M:$M,DB!$M34) -> 79 | O34: =COUNTIFS('FY 26_qualification scenario'!$BI:$BI,DB!O$4,'FY 26_qualification scenario'!$I:$I,DB!$K34,'FY 26_qualification scenario'!$F:$F,DB!$L34,'FY 26_qualification scenario'!$M:$M,DB!$M34) -> 3 | P34: =COUNTIFS('FY 26_qualification scenario'!$BI:$BI,DB!P$4,'FY 26_qualification scenario'!$I:$I,DB!$K34,'FY 26_qualification scenario'!$F:$F,DB!$L34,'FY 26_qualification scenario'!$M:$M,DB!$M34) -> 2 | Q34: =COUNTIFS('FY 26_qualification scenario'!$BI:$BI,DB!Q$4,'FY 26_qualification scenario'!$I:$I,DB!$K34,'FY 26_qualification scenario'!$F:$F,DB!$L34,'FY 26_qualification scenario'!$M:$M,DB!$M34) -> 2 | R34: =COUNTIFS('FY 26_qualification scenario'!$BI:$BI,DB!R$4,'FY 26_qualification scenario'!$I:$I,DB!$K34,'FY 26_qualification scenario'!$F:$F,DB!$L34,'FY 26_qualification scenario'!$M:$M,DB!$M34) -> 1 | S34: =COUNTIFS('FY 26_qualification scenario'!$BI:$BI,DB!S$4,'FY 26_qualification scenario'!$I:$I,DB!$K34,'FY 26_qualification scenario'!$F:$F,DB!$L34,'FY 26_qualification scenario'!$M:$M,DB!$M34) -> 1
K35: Maheshwari Traders | L35: WEST BENGAL | M35: East | N35: =COUNTIFS('FY 26_qualification scenario'!$I:$I,DB!$K35,'FY 26_qualification scenario'!$F:$F,DB!$L35,'FY 26_qualification scenario'!$M:$M,DB!$M35) -> 18 | O35: =COUNTIFS('FY 26_qualification scenario'!$BI:$BI,DB!O$4,'FY 26_qualification scenario'!$I:$I,DB!$K35,'FY 26_qualification scenario'!$F:$F,DB!$L35,'FY 26_qualification scenario'!$M:$M,DB!$M35) -> 0 | P35: =COUNTIFS('FY 26_qualification scenario'!$BI:$BI,DB!P$4,'FY 26_qualification scenario'!$I:$I,DB!$K35,'FY 26_qualification scenario'!$F:$F,DB!$L35,'FY 26_qualification scenario'!$M:$M,DB!$M35) -> 0 | Q35: =COUNTIFS('FY 26_qualification scenario'!$BI:$BI,DB!Q$4,'FY 26_qualification scenario'!$I:$I,DB!$K35,'FY 26_qualification scenario'!$F:$F,DB!$L35,'FY 26_qualification scenario'!$M:$M,DB!$M35) -> 0 | R35: =COUNTIFS('FY 26_qualification scenario'!$BI:$BI,DB!R$4,'FY 26_qualification scenario'!$I:$I,DB!$K35,'FY 26_qualification scenario'!$F:$F,DB!$L35,'FY 26_qualification scenario'!$M:$M,DB!$M35) -> 0 | S35: =COUNTIFS('FY 26_qualification scenario'!$BI:$BI,DB!S$4,'FY 26_qualification scenario'!$I:$I,DB!$K35,'FY 26_qualification scenario'!$F:$F,DB!$L35,'FY 26_qualification scenario'!$M:$M,DB!$M35) -> 0
K36: MEWARAM MADHUSUDAN PRASAD & SONS | L36: BIHAR | M36: East | N36: =COUNTIFS('FY 26_qualification scenario'!$I:$I,DB!$K36,'FY 26_qualification scenario'!$F:$F,DB!$L36,'FY 26_qualification scenario'!$M:$M,DB!$M36) -> 14 | O36: =COUNTIFS('FY 26_qualification scenario'!$BI:$BI,DB!O$4,'FY 26_qualification scenario'!$I:$I,DB!$K36,'FY 26_qualification scenario'!$F:$F,DB!$L36,'FY 26_qualification scenario'!$M:$M,DB!$M36) -> 0 | P36: =COUNTIFS('FY 26_qualification scenario'!$BI:$BI,DB!P$4,'FY 26_qualification scenario'!$I:$I,DB!$K36,'FY 26_qualification scenario'!$F:$F,DB!$L36,'FY 26_qualification scenario'!$M:$M,DB!$M36) -> 0 | Q36: =COUNTIFS('FY 26_qualification scenario'!$BI:$BI,DB!Q$4,'FY 26_qualification scenario'!$I:$I,DB!$K36,'FY 26_qualification scenario'!$F:$F,DB!$L36,'FY 26_qualification scenario'!$M:$M,DB!$M36) -> 0 | R36: =COUNTIFS('FY 26_qualification scenario'!$BI:$BI,DB!R$4,'FY 26_qualification scenario'!$I:$I,DB!$K36,'FY 26_qualification scenario'!$F:$F,DB!$L36,'FY 26_qualification scenario'!$M:$M,DB!$M36) -> 0 | S36: =COUNTIFS('FY 26_qualification scenario'!$BI:$BI,DB!S$4,'FY 26_qualification scenario'!$I:$I,DB!$K36,'FY 26_qualification scenario'!$F:$F,DB!$L36,'FY 26_qualification scenario'!$M:$M,DB!$M36) -> 0
... K69: Urbanspan Infrastructure Pvt Ltd | L69: MADHYA PRADESH | M69: Central | N69: =COUNTIFS('FY 26_qualification scenario'!$I:$I,DB!$K69,'FY 26_qualification scenario'!$F:$F,DB!$L69,'FY 26_qualification scenario'!$M:$M,DB!$M69) -> 2 | O69: =COUNTIFS('FY 26_qualification scenario'!$BI:$BI,DB!O$4,'FY 26_qualification scenario'!$I:$I,DB!$K69,'FY 26_qualification scenario'!$F:$F,DB!$L69,'FY 26_qualification scenario'!$M:$M,DB!$M69) -> 0 | P69: =COUNTIFS('FY 26_qualification scenario'!$BI:$BI,DB!P$4,'FY 26_qualification scenario'!$I:$I,DB!$K69,'FY 26_qualification scenario'!$F:$F,DB!$L69,'FY 26_qualification scenario'!$M:$M,DB!$M69) -> 0 | Q69: =COUNTIFS('FY 26_qualification scenario'!$BI:$BI,DB!Q$4,'FY 26_qualification scenario'!$I:$I,DB!$K69,'FY 26_qualification scenario'!$F:$F,DB!$L69,'FY 26_qualification scenario'!$M:$M,DB!$M69) -> 0 | R69: =COUNTIFS('FY 26_qualification scenario'!$BI:$BI,DB!R$4,'FY 26_qualification scenario'!$I:$I,DB!$K69,'FY 26_qualification scenario'!$F:$F,DB!$L69,'FY 26_qualification scenario'!$M:$M,DB!$M69) -> 0 | S69: =COUNTIFS('FY 26_qualification scenario'!$BI:$BI,DB!S$4,'FY 26_qualification scenario'!$I:$I,DB!$K69,'FY 26_qualification scenario'!$F:$F,DB!$L69,'FY 26_qualification scenario'!$M:$M,DB!$M69) -> 0
K70: Total | N70: =SUM(N5:N69) -> 1745 | O70: =SUM(O5:O69) -> 50 | P70: =SUM(P5:P69) -> 59 | Q70: =SUM(Q5:Q69) -> 25 | R70: =SUM(R5:R69) -> 41 | S70: =SUM(S5:S69) -> 9

Sheet FY 26_qualification Expected
A1: {='[1]Consol. dealer sales_FY 25 + 26'!$A$2:$AV$1800} -> Sr No. | B1: Year | C1: Retailer Code | D1: Account Sf ID | E1: Name of the Dealer | F1: State | G1: District | H1: Taluka | I1: Distributor Name | J1: Account Owner As per SF | K1: TM | L1: Distributor Code | M1: Zone | N1: Pin code | O1: GST No. | P1: Mobile No. | Q1: Onboarded Dealer Months | R1: Year of Onboarding (FY) | S1: Sales FY24 | T1: Counter Potential / month | U1: Share of Business (%) | V1: Dealer Segmentation | W1: 45292 | X1: 45323 | Y1: 45352 | Z1: 45383 | AA1: 45413 | AB1: 45444 | AC1: 45474 | AD1: 45505 | AE1: 45536 | AF1: 45566 | AG1: 45597 | AH1: 45627 | AI1: 45658 | AJ1: 45689 | AK1: 45717 | AL1: 45748 | AM1: 45778 | AN1: 45809 | AO1: 45839 | AP1: 45870 | AQ1: 45901 | AR1: 45931 | AS1: 45962 | AT1: 45992 | AU1: 46023 | AV1: 46054 | AW1: Actual Apr'25 to Jan'26 | AX1: Recommend Vol. Nov to Mar'26 | AY1: FY 26 total | AZ1: FY 25 vol. | BA1: Sales recommend Vol. FY 26 | BB1: Balance Vol FY 26 | BC1: RR/Month | BD1: Y-o-Y Growth | BE1: Vol. gap (FY 25 - Oct 25 TD) | BF1: Distributor self-counter (Yes/No) | BG1: Avg. monthly vol. | BH1: Applicable for scheme (Yes/No) | BI1: Sales recommended vol. FY 26 | BJ1: Category | BK1: H2 BE | BL1: H1 | BM1: % H2 sales | BN1: % H1 sales | BO1: Sales TD | BP1: Current scheme slab | BQ1: Remarks | BR1: H1 | BS1: H2 | BT1: Total | BU1: FY 25 Qualifier | BV1: Category | BX1: Status | BY1: Changes | BZ1: Recommend Vol. | CB1: Up to Oct-25 | CC1: Nov to Mar | CG1: Bucketing wise | CH1: Category | CI1: Category for Non Qualifier Dealer | CK1: FY 25 Qualifier Domestic | CV1: 45292 | CW1: 45323 | CX1: 45352 | CY1: 45383 | CZ1: 45413 | DA1: 45444 | DB1: 45474 | DC1: 45505 | DD1: 45536 | DE1: 45566 | DF1: 45597 | DG1: 45627 | DH1: 45658 | DI1: 45689 | DJ1: 45717 | DK1: 45748 | DL1: 45778 | DM1: 45809 | DN1: 45839 | DO1: 45870 | DP1: 45901 | DQ1: 45931 | DR1: 45962 | DS1: 45992
A2: 1 | B2: 2023 | C2: PBTMTR211 | D2: 0015g00001UBHkRAAX | E2: M/S SHRI NIRMAL KUMAR JAIN & CO. | F2: UTTAR PRADESH | G2: KANPUR NAGAR | H2: Fazalganj | I2: SHREE LAKSHMAN ROLLING MILL (INDIA) LLP | J2: Ashutosh Shukla | K2: - | L2: C12815 | M2: North | N2: 208012 | O2: 09AAOPJ4618H1ZG | P2: 8808060004 | Q2: Nov'23 | R2: 2024 | S2: 296 | T2: 1500 | U2: 0.19833333 | V2: Super Star | W2: 95 | X2: 96 | Y2: 75 | Z2: 4 | AA2: 263.925 | AB2: 133 | AC2: 0 | AD2: 394 | AE2: 52 | AF2: 189 | AG2: 90 | AH2: 168 | AI2: 107.91 | AJ2: 568.38 | AK2: 596 | AL2: 520 | AM2: 216 | AN2: 137 | AO2: 98.81 | AP2: 182.48 | AQ2: 344.25 | AR2: 110.39 | AS2: 184 | AT2: 270 | AU2: 200 | AV2: 422.5 | AW2: =SUM(AL2:AU2) -> 2262.93 | AX2: 3217.86 | AY2: =AW2+AX2 -> 5480.79 | AZ2: =SUM(Z2:AK2) -> 2566.215 | BA2: 3400 | BB2: =BA2-AW2 -> 1137.07 | BC2: =IFERROR(BB2/4,0) -> 284.2675 | BD2: =AY2-AZ2 -> 2914.575 | BE2: =AZ2-AW2 -> 303.285 | BF2: Yes | BG2: =AVERAGE(AL2:AS2) -> 224.11625 | BH2: No | BI2: =IF(BF2="Yes","", IF(BA2>1250,"E", IF(BA2>750,"D", IF(BA2>=500,"C", IF(BA2>=300,"B", IF(BA2>=200,"A", IF(BA2<200,"<200",""))))))) | BJ2: =IF(BF2="Yes","",IF(AY2>1250,"E",IF(AY2>750,"D", IF(AY2>=500,"C", IF(AY2>=300,"B", IF(AY2>=200,"A", "")))))) | BK2: =SUM(AR2:AX2) -> 6667.68 | BL2: =SUM(AL2:AQ2) -> 1498.54 | BM2: =IFERROR(BK2/$AY2,"") -> 1.2165545 | BN2: =IFERROR(BL2/$AY2,"") -> 0.27341679 | BO2: =SUM(AL2:AS2) -> 1792.93 | BP2: =IF(BF2="Yes","",IF(BO2>1250,"E",IF(BO2>750,"D", IF(BO2>=500,"C", IF(BO2>=300,"B", IF(BO2>=200,"A", "")))))) | BR2: =SUM(Z2:AE2) -> 846.925 | BS2: =SUM(AF2:AK2) -> 1719.29 | BT2: =SUM(BR2:BS2) -> 2566.215 | BU2: =IFERROR(_xlfn.XLOOKUP(D2,Sheet1!B:B,Sheet1!L:L),"") | BV2: =_xlfn.XLOOKUP(BU2,Sheet1!S:S,Sheet1!T:T) -> #N/A | BW2: =_xlfn.XLOOKUP(D2,Sheet1!B:B,Sheet1!M:M) -> #N/A | BZ2: =AY2-AW2 -> 3217.86 | CB2: =AW2/AY2 -> 0.41288391 | CC2: =AX2/AY2 -> 0.58711609 | CE2: =AW2/CB2*CC2 -> 3217.86 | CG2: =IF(BO2<80,"Below 80", IF(BO2<=120,"80-120", IF(BO2<=200,"> 120-200", IF(BO2<=300,">200-300", IF(BO2<=500,">300-500", ">500"))))) -> >500 | CH2: =IFERROR(_xlfn.XLOOKUP(CG2,Scenario!M:M,Scenario!N:N),"") -> E | CI2: =IF(BI2="", IF(BA2>=1, "Yes", "No")) -> Yes | CJ2: 3033.86 | CT2: # | CU2: Rajasthan | CV2: =COUNTIFS($F:$F,$CU2,W:W,">0") -> 15 | CW2: =COUNTIFS($F:$F,$CU2,X:X,">0") -> 14 | CX2: =COUNTIFS($F:$F,$CU2,Y:Y,">0") -> 13 | CY2: =COUNTIFS($F:$F,$CU2,Z:Z,">0") -> 20 | CZ2: =COUNTIFS($F:$F,$CU2,AA:AA,">0") -> 28 | DA2: =COUNTIFS($F:$F,$CU2,AB:AB,">0") -> 11 | DB2: =COUNTIFS($F:$F,$CU2,AC:AC,">0") -> 13 | DC2: =COUNTIFS($F:$F,$CU2,AD:AD,">0") -> 14 | DD2: =COUNTIFS($F:$F,$CU2,AE:AE,">0") -> 14 | DE2: =COUNTIFS($F:$F,$CU2,AF:AF,">0") -> 34 | DF2: =COUNTIFS($F:$F,$CU2,AG:AG,">0") -> 19 | DG2: =COUNTIFS($F:$F,$CU2,AH:AH,">0") -> 42 | DH2: =COUNTIFS($F:$F,$CU2,AI:AI,">0") -> 34 | DI2: =COUNTIFS($F:$F,$CU2,AJ:AJ,">0") -> 36 | DJ2: =COUNTIFS($F:$F,$CU2,AK:AK,">0") -> 38 | DK2: =COUNTIFS($F:$F,$CU2,AL:AL,">0") -> 33 | DL2: =COUNTIFS($F:$F,$CU2,AM:AM,">0") -> 30 | DM2: =COUNTIFS($F:$F,$CU2,AN:AN,">0") -> 25 | DN2: =COUNTIFS($F:$F,$CU2,AO:AO,">0") -> 34 | DO2: =COUNTIFS($F:$F,$CU2,AP:AP,">0") -> 23 | DP2: =COUNTIFS($F:$F,$CU2,AQ:AQ,">0") -> 27 | DQ2: =COUNTIFS($F:$F,$CU2,AR:AR,">0") -> 26 | DY2: Current #
A3: 2 | B3: 2023 | C3: PBTMTR18 | D3: 0015g00001V9fpAAAR | E3: ALLAHABAD IRON AND STEEL COMPANY | F3: UTTAR PRADESH | G3: PRAYAGRAJ | H3: Prayagraj | I3: GLOBAL IRONTRADING PVT. LTD. | J3: Divyansh Dhawal | K3: Varun Arora | L3: C12819 | M3: North | N3: 211008 | O3: 09BDAPS4881H1Z5 | P3: 9956563784 | Q3: Nov'23 | R3: 2024 | S3: 150 | T3: 200 | U3: 0.0416 | V3: Challenger | W3: 30 | X3: 30 | Y3: 30 | Z3: 30 | AA3: 35.04 | AB3: 0 | AC3: 51 | AD3: 0 | AE3: 0 | AF3: 30 | AG3: 0 | AH3: 35 | AI3: 0 | AJ3: 0 | AK3: 0 | AL3: 0 | AM3: 20 | AN3: 15 | AO3: 25.03 | AP3: 0 | AQ3: 24.95 | AR3: 0 | AS3: 25.14 | AT3: 24.96 | AU3: 0 | AV3: 0 | AW3: =SUM(AL3:AU3) -> 135.08 | AX3: 216.02 | AY3: 301 | AZ3: =SUM(Z3:AK3) -> 181.04 | BA3: =AW3+120 -> 255.08 | BB3: =BA3-AW3 -> 120 | BC3: =IFERROR(BB3/4,0) -> 30 | BD3: =AY3-AZ3 -> 119.96 | BE3: =AZ3-AW3 -> 45.96 | BF3: No | BG3: =AVERAGE(AL3:AS3) -> 13.765 | BH3: Yes | BI3: =IF(BF3="Yes","",IF(BA3>1250,"E",IF(BA3>750,"D", IF(BA3>=500,"C", IF(BA3>=300,"B", IF(BA3>=200,"A", "")))))) -> A | BJ3: =IF(BF3="Yes","",IF(AY3>1250,"E",IF(AY3>750,"D", IF(AY3>=500,"C", IF(AY3>=300,"B", IF(AY3>=200,"A", "")))))) -> B | BK3: =SUM(AR3:AX3) -> 401.2 | BL3: =SUM(AL3:AQ3) -> 84.98 | BM3: =IFERROR(BK3/$AY3,"") -> 1.3328904 | BN3: =IFERROR(BL3/$AY3,"") -> 0.28232558 | BO3: =SUM(AL3:AS3) -> 110.12 | BP3: =IF(BF3="Yes","",IF(BO3>1250,"E",IF(BO3>750,"D", IF(BO3>=500,"C", IF(BO3>=300,"B", IF(BO3>=200,"A", "")))))) | BR3: =SUM(Z3:AE3) -> 116.04 | BS3: =SUM(AF3:AK3) -> 65 | BT3: =SUM(BR3:BS3) -> 181.04 | BU3: =IFERROR(_xlfn.XLOOKUP(D3,Sheet1!B:B,Sheet1!L:L),"") | BV3: =_xlfn.XLOOKUP(BU3,Sheet1!S:S,Sheet1!T:T) -> #N/A | BW3: =_xlfn.XLOOKUP(D3,Sheet1!B:B,Sheet1!M:M) -> #N/A | BX3: New | BY3: 301 | BZ3: =AY3-AW3 -> 165.92 | CB3: =AW3/AY3 -> 0.44877076 | CC3: =AX3/AY3 -> 0.71767442 | CE3: =AW3/CB3*CC3 -> 216.02 | CG3: =IF(BO3<80,"Below 80", IF(BO3<=120,"80-120", IF(BO3<=200,"> 120-200", IF(BO3<=300,">200-300", IF(BO3<=500,">300-500", ">500"))))) -> 80-120 | CH3: =IFERROR(_xlfn.XLOOKUP(CG3,Scenario!M:M,Scenario!N:N),"") -> A | CI3: =IF(BI3="", IF(BA3>=1, "Yes", "No")) -> FALSE | CJ3: 190.88 | CT3: Volume | CU3: Rajasthan | CV3: =SUMIFS(W:W,$F:$F,$CU3) -> 311 | CW3: =SUMIFS(X:X,$F:$F,$CU3) -> 308 | CX3: =SUMIFS(Y:Y,$F:$F,$CU3) -> 361 | CY3: =SUMIFS(Z:Z,$F:$F,$CU3) -> 423 | CZ3: =SUMIFS(AA:AA,$F:$F,$CU3) -> 782.34 | DA3: =SUMIFS(AB:AB,$F:$F,$CU3) -> 381 | DB3: =SUMIFS(AC:AC,$F:$F,$CU3) -> 422.05 | DC3: =SUMIFS(AD:AD,$F:$F,$CU3) -> 437.54 | DD3: =SUMIFS(AE:AE,$F:$F,$CU3) -> 805.29 | DE3: =SUMIFS(AF:AF,$F:$F,$CU3) -> 1261.12 | DF3: =SUMIFS(AG:AG,$F:$F,$CU3) -> 767 | DG3: =SUMIFS(AH:AH,$F:$F,$CU3) -> 1456.99 | DH3: =SUMIFS(AI:AI,$F:$F,$CU3) -> 1279.3 | DI3: =SUMIFS(AJ:AJ,$F:$F,$CU3) -> 1553.05 | DJ3: =SUMIFS(AK:AK,$F:$F,$CU3) -> 1609.49 | DK3: =SUMIFS(AL:AL,$F:$F,$CU3) -> 1728.83 | DL3: =SUMIFS(AM:AM,$F:$F,$CU3) -> 1349.04 | DM3: =SUMIFS(AN:AN,$F:$F,$CU3) -> 1134.6 | DN3: =SUMIFS(AO:AO,$F:$F,$CU3) -> 1279.92 | DO3: =SUMIFS(AP:AP,$F:$F,$CU3) -> 1064.37 | DP3: =SUMIFS(AQ:AQ,$F:$F,$CU3) -> 885.12 | DQ3: =SUMIFS(AR:AR,$F:$F,$CU3) -> 624.22 | DY3: # Qualified dealers | DZ3: Qualified volume | EA3: Avg. lifting/dealer/slab | EB3: Amount
